<?xml version="1.0" ?>
<sdf version="1.8">
    <world name="elgooso_world">
        <physics name="1ms" type="ignored">
            <max_step_size>0.001</max_step_size>
            <real_time_factor>1.0</real_time_factor>
        </physics>
        <plugin
            filename="libignition-gazebo-physics-system.so"
            name="ignition::gazebo::systems::Physics">
        </plugin>
        <plugin
            filename="libignition-gazebo-user-commands-system.so"
            name="ignition::gazebo::systems::UserCommands">
        </plugin>
        <plugin
            filename="libignition-gazebo-scene-broadcaster-system.so"
            name="ignition::gazebo::systems::SceneBroadcaster">
        </plugin>
        <plugin
		  filename="libignition-gazebo-sensors-system.so"
		  name="ignition::gazebo::systems::Sensors">
		  <render_engine>ogre2</render_engine>
		</plugin>
        
        <light type="directional" name="sun">
            <cast_shadows>true</cast_shadows>
            <pose>0 0 10 0 0 0</pose>
            <diffuse>0.8 0.8 0.8 1</diffuse>
            <specular>0.2 0.2 0.2 1</specular>
            <attenuation>
                <range>1000</range>
                <constant>0.9</constant>
                <linear>0.01</linear>
                <quadratic>0.001</quadratic>
            </attenuation>
            <direction>-0.5 0.1 -0.9</direction>
        </light>

        <model name="ground_plane">
            <static>true</static>
            <link name="link">
                <collision name="collision">
                <geometry>
                    <plane>
		                <normal>0 0 1</normal>
                    </plane>
                </geometry>
                </collision>
                <visual name="visual">
                <geometry>
                    <plane>
		                <normal>0 0 1</normal>
		                <size>10 10</size>
                    </plane>
                </geometry>
                <material>
                    <ambient>0.8 0.8 0.8 1</ambient>
                    <diffuse>0.8 0.8 0.8 1</diffuse>
                    <specular>0.8 0.8 0.8 1</specular>
                </material>
                </visual>
            </link>
        </model>
        
        <model name='wall'>
			<static>true</static>
			<pose>5 0 0 0 0 0</pose><!--pose relative to the world-->
			<link name='box'>
				<pose/>
				<visual name='visual'>
				    <geometry>
				        <box>
				            <size>0.5 10.0 2.0</size>
				        </box>
				    </geometry>
				    <!--let's add color to our link-->
				    <material>
				        <ambient>0.0 0.0 1.0 1</ambient>
				        <diffuse>0.0 0.0 1.0 1</diffuse>
				        <specular>0.0 0.0 1.0 1</specular>
				    </material>
				</visual>
				<collision name='collision'>
				    <geometry>
				        <box>
				            <size>0.5 10.0 2.0</size>
				        </box>
				    </geometry>
				</collision>
			</link>
		</model>
        
        
        <model name="elgooso" canonical_link='body'>
        	<pose relative_to='world'>0 0 0.045 0 0 0 </pose>
        	
			<link name="body">
				<pose relative_to='__model__'>0 0 0 0 0 0</pose>
				<inertial>
				  <mass>0.5"</mass>
				  <inertia> 
				  	<ixx>1e-3</ixx> 
				  	<ixy>0.0</ixy> 
				  	<ixz>0.0</ixz>
				  	<iyy>5e-4</iyy>
				  	<iyz>0.0</iyz>
				  	<izz>1e-3</izz>
				  </inertia>
				</inertial>
				<visual name='visual'>
				  <geometry>
				  	<box>
						<size>0.15 0.1 0.05</size>
					</box>
				  </geometry>
				  <material>
				  	<ambient>0.0 0.0 0.0 1</ambient>
				  	<diffuse>0.0 0.0 0.0 1</diffuse>
				  	<specular>0.0 0.0 0.0 1</specular>
				  </material>
				</visual>
				<collision name='collision'>
				  <geometry>
				  	<box>
						<size>0.15 0.1 0.05</size>
					</box>
				  </geometry>
				</collision>
				</link>
		  
			<link name="neck">
				<pose relative_to='body'>0.070 0 0.03 0 0 0</pose>
				<inertial>
				  <mass>0.01"</mass>
				  <inertia> 
				  	<ixx>1e-7</ixx> 
				  	<ixy>0.0</ixy> 
				  	<ixz>0.0</ixz>
				  	<iyy>1e-7</iyy>
				  	<iyz>0.0</iyz>
				  	<izz>1e-7</izz>
				  </inertia>
				</inertial>
				<visual name='visual'>
				  <geometry>
					<cylinder> 
						<length>0.01</length> 
						<radius>0.005"</radius>
					</cylinder>
				  </geometry>
				  <material>
				  	<ambient>1.0 1.0 1.0 1</ambient>
				  	<diffuse>1.0 1.0 1.0 1</diffuse>
				  	<specular>1.0 1.0 1.0 1</specular>
				  </material>
				</visual>
			</link>
			<joint name="body_to_neck" type="revolute">
				<axis>
					<xyz>0 1 0"</xyz>
					<limit> 
						<effort>1000.0</effort> 
						<lower>-0.785398</lower> 
						<upper>0.785398</upper>
						<velocity>0.025</velocity>
					</limit>
				</axis>
				<parent>body</parent>
				<child>neck</child>
			</joint>
		  
			<frame name="sonar_frame" attached_to='head'>
				<pose>0.8 0 0.5 0 0 0</pose>
			</frame>
		  
			<link name="head">
				<pose relative_to='neck'>0 0 0.015 0 0 0</pose>
			  	<inertial>
				  <mass>0.01"</mass>
				  <inertia> 
				  	<ixx>1e-6</ixx> 
				  	<ixy>0.0</ixy> 
				  	<ixz>0.0</ixz>
				  	<iyy>1e-6</iyy>
				  	<iyz>0.0</iyz>
				  	<izz>2e-6</izz>
				  </inertia>
				</inertial>
				<visual name='visual'>
				  <geometry>
				  	<box>
						<size>0.001 0.04 0.02</size>
					</box>
				  </geometry>
				  <material>
				  	<ambient>1.0 0.40 0 1</ambient>
				  	<diffuse>1.0 0.40 0 1</diffuse>
				  	<specular>1.0 0.40 0 1</specular>
				  </material>
				</visual>
				<collision name='collision'>
				  <geometry>
				  	<box>
						<size>0.1 0.1 0.1</size>
					</box>
				  </geometry>
				</collision>
				<sensor name='sonar' type='gpu_lidar'>"
					<pose relative_to='sonar_frame'>0 0 0 0 0 0</pose>
					<topic>sonar</topic>
					<update_rate>5</update_rate>
					<ray>
						<scan>
							<horizontal>
								<samples>2</samples>
								<resolution>1.0</resolution>
								<min_angle>-0.25</min_angle>
								<max_angle>0.25</max_angle>
							</horizontal>
							<vertical>
								<samples>2</samples>
								<resolution>1.0</resolution>
								<min_angle>0.25</min_angle>
								<max_angle>0.25</max_angle>
							</vertical>
						</scan>
						<range>
							<min>0.08</min>
							<max>3.0</max>
							<resolution>0.01</resolution>
						</range>
					</ray>
					<always_on>1</always_on>
					<visualize>true</visualize>
				</sensor>
			</link>
			<joint name="neck_to_head" type="fixed">
				<parent>neck</parent>
				<child>head</child>
			</joint>
		  
		  <link name="right_ear">
		  	<pose relative_to='head'>0.005 0.006 0 0 1.5708 0</pose>
		  	<inertial>
			  <mass>0.01"</mass>
			  <inertia> 
			  	<ixx>1e-7</ixx> 
			  	<ixy>0.0</ixy> 
			  	<ixz>0.0</ixz>
			  	<iyy>1e-7</iyy>
			  	<iyz>0.0</iyz>
			  	<izz>1e-7</izz>
			  </inertia>
			</inertial>
			<visual name='visual'>
			  <geometry>
			  	<cylinder> 
					<length>0.01</length> 
					<radius>0.005"</radius>
				</cylinder>
			  </geometry>
			  <material>
			  	<ambient>0.82 0.82 0.82 1</ambient>
			  	<diffuse>0.82 0.82 0.82 1</diffuse>
			  	<specular>0.82 0.82 0.82 1</specular>
			  </material>
			</visual>
		  </link>
		  <joint name="head_to_right_ear" type="fixed">
		  	<parent>head</parent>
			<child>right_ear</child>
		  </joint>
		  
		  <link name="left_ear">
		  	<pose relative_to='head'>0.005 -0.006 0 0 1.5708 0</pose>
		  	<inertial>
			  <mass>0.01"</mass>
			  <inertia> 
			  	<ixx>1e-7</ixx> 
			  	<ixy>0.0</ixy> 
			  	<ixz>0.0</ixz>
			  	<iyy>1e-7</iyy>
			  	<iyz>0.0</iyz>
			  	<izz>1e-7</izz>
			  </inertia>
			</inertial>
			<visual name='visual'>
			  <geometry>
			  	<cylinder> 
					<length>0.01</length> 
					<radius>0.005"</radius>
				</cylinder>
			  </geometry>
			  <material>
			  	<ambient>0.82 0.82 0.82 1</ambient>
			  	<diffuse>0.82 0.82 0.82 1</diffuse>
			  	<specular>0.82 0.82 0.82 1</specular>
			  </material>
			</visual>
		  </link>
		  <joint name="head_to_left_ear" type="fixed">
		  	<parent>head</parent>
			<child>left_ear</child>
		  </joint>
		  
		  <link name="left_front_wheel">
		  	<pose relative_to='body'>0.045 0.06 -0.01 -1.5708 0 0</pose>
		  	<inertial>
			  <mass>0.1</mass>
			  <inertia> 
			  	<ixx>2e-4</ixx> 
			  	<ixy>0.0</ixy> 
			  	<ixz>0.0</ixz>
			  	<iyy>2e-4</iyy>
			  	<iyz>0.0</iyz>
			  	<izz>4e-4</izz>
			  </inertia>
			</inertial>
			<visual name='visual'>
			  <geometry>
			  	<cylinder> 
					<length>0.02</length> 
					<radius>0.035"</radius>
				</cylinder>
			  </geometry>
			  <material>
			  	<ambient>1.0 1.0 0.0 1</ambient>
			  	<diffuse>1.0 1.0 0.0 1</diffuse>
			  	<specular>1.0 1.0 0.0 1</specular>
			  </material>
			</visual>
			<collision name='collision'>
			  <geometry>
			  	<cylinder> 
					<length>0.02</length> 
					<radius>0.035"</radius>
				</cylinder>
			  </geometry>
			</collision>
		  </link>
		  <joint name="body_to_left_front_wheel" type="revolute">
		  	<parent>body</parent>
			<child>left_front_wheel</child>
			<axis> 
				<xyz>0 0 1"</xyz>
				<limit>
					<lower>-1.79769e+308</lower>
					<upper>1.79769e+308</upper>
				</limit>
			</axis>
		  </joint>
		  
		  <link name="right_front_wheel">
		  	<pose relative_to='body'>0.045 -0.06 -0.01 -1.5708 0 0</pose>
		  	<inertial>
			  <mass>0.1</mass>
			  <inertia> 
			  	<ixx>2e-4</ixx> 
			  	<ixy>0.0</ixy> 
			  	<ixz>0.0</ixz>
			  	<iyy>2e-4</iyy>
			  	<iyz>0.0</iyz>
			  	<izz>4e-4</izz>
			  </inertia>
			</inertial>
			<visual name='visual'>
			  <geometry>
			  	<cylinder> 
					<length>0.02</length> 
					<radius>0.035"</radius>
				</cylinder>
			  </geometry>
			  <material>
			  	<ambient>1.0 1.0 0.0 1</ambient>
			  	<diffuse>1.0 1.0 0.0 1</diffuse>
			  	<specular>1.0 1.0 0.0 1</specular>
			  </material>
			</visual>
			<collision name='collision'>
			  <geometry>
			  	<cylinder> 
					<length>0.02</length> 
					<radius>0.035"</radius>
				</cylinder>
			  </geometry>
			</collision>
		  </link>
		  <joint name="body_to_right_front_wheel" type="revolute">
			<parent>body</parent>
			<child>right_front_wheel</child>
			<axis> 
				<xyz>0 0 1</xyz>
				<limit>
					<lower>-1.79769e+308</lower>
					<upper>1.79769e+308</upper>
				</limit>
		  	</axis>
		  </joint>
		  
		  <link name="left_back_wheel">
		  	<pose relative_to='body'>-0.045 0.06 -0.01 -1.5708 0 0</pose>
		  	<inertial>
			  <mass>0.1</mass>
			  <inertia> 
			  	<ixx>2e-4</ixx> 
			  	<ixy>0.0</ixy> 
			  	<ixz>0.0</ixz>
			  	<iyy>2e-4</iyy>
			  	<iyz>0.0</iyz>
			  	<izz>4e-4</izz>
			  </inertia>
			</inertial>
			<visual name='visual'>
			  <geometry>
			  	<cylinder> 
					<length>0.02</length> 
					<radius>0.035"</radius>
				</cylinder>
			  </geometry>
			  <material>
			  	<ambient>1.0 1.0 0.0 1</ambient>
			  	<diffuse>1.0 1.0 0.0 1</diffuse>
			  	<specular>1.0 1.0 0.0 1</specular>
			  </material>
			</visual>
			<collision name='collision'>
			  <geometry>
			  	<cylinder> 
					<length>0.02</length> 
					<radius>0.035"</radius>
				</cylinder>
			  </geometry>
			</collision>
		  </link>
		  <joint name="body_to_left_back_wheel" type="revolute">
		  	<parent>body</parent>
			<child>left_back_wheel</child>
			<axis> 
				<xyz>0 0 1</xyz>
				<limit>
					<lower>-1.79769e+308</lower>
					<upper>1.79769e+308</upper>
				</limit>
		  	</axis>
		  </joint>
		  
		  <link name="right_back_wheel">
		  	<pose relative_to='body'>-0.045 -0.06 -0.01 -1.5708 0 0</pose>
		  	<inertial>
			  <mass>0.1</mass>
			  <inertia> 
			  	<ixx>2e-4</ixx> 
			  	<ixy>0.0</ixy> 
			  	<ixz>0.0</ixz>
			  	<iyy>2e-4</iyy>
			  	<iyz>0.0</iyz>
			  	<izz>4e-4</izz>
			  </inertia>
			</inertial>
			<visual name='visual'>
			  <geometry>
			  	<cylinder> 
					<length>0.02</length> 
					<radius>0.035"</radius>
				</cylinder>
			  </geometry>
			  <material>
			  	<ambient>1.0 1.0 0.0 1</ambient>
			  	<diffuse>1.0 1.0 0.0 1</diffuse>
			  	<specular>1.0 1.0 0.0 1</specular>
			  </material>
			</visual>
			<collision name='collision'>
			  <geometry>
			  	<cylinder> 
					<length>0.02</length> 
					<radius>0.035"</radius>
				</cylinder>
			  </geometry>
			</collision>
		  </link>
		  <joint name="body_to_right_back_wheel" type="revolute">
		  	<parent>body</parent>
			<child>right_back_wheel</child>
			<axis> 
				<xyz>0 0 1</xyz>
				<limit>
					<lower>-1.79769e+308</lower>
					<upper>1.79769e+308</upper>
				</limit>
		  	</axis>
		  </joint>
		  
		  <plugin
			filename="libignition-gazebo-diff-drive-system"
			name="ignition::gazebo::systems::DiffDrive">
			<left_joint>body_to_left_front_wheel</left_joint>
			<left_joint>body_to_left_back_wheel</left_joint>
			<right_joint>body_to_right_front_wheel</right_joint>
			<right_joint>body_to_right_back_wheel</right_joint>
			<wheel_separation>0.1</wheel_separation>
			<wheel_radius>0.035</wheel_radius>
			<!--<odom_publish_frequency>1</odom_publish_frequency>
			<topic>cmd_vel</topic>-->
			</plugin>
			
			<!-- Moving Forward-->
		    <plugin filename="libignition-gazebo-triggered-publisher-system.so"
		            name="ignition::gazebo::systems::TriggeredPublisher">
		        <input type="ignition.msgs.Int32" topic="/keyboard/keypress">
		            <match field="data">16777235</match>
		        </input>
		        <output type="ignition.msgs.Twist" topic="/model/elgooso/cmd_vel">
		            linear: {x: 0.5}, angular: {z: 0.0}
		        </output>
		    </plugin>

		    <!-- Moving Backward-->
		    <plugin filename="libignition-gazebo-triggered-publisher-system.so"
		            name="ignition::gazebo::systems::TriggeredPublisher">
		        <input type="ignition.msgs.Int32" topic="/keyboard/keypress">
		            <match field="data">16777237</match>
		        </input>
		        <output type="ignition.msgs.Twist" topic="/model/elgooso/cmd_vel">
		            linear: {x: -0.5}, angular: {z: 0.0}
		        </output>
		    </plugin>

		    <!-- Rotating right-->
		    <plugin filename="libignition-gazebo-triggered-publisher-system.so"
		            name="ignition::gazebo::systems::TriggeredPublisher">
		        <input type="ignition.msgs.Int32" topic="/keyboard/keypress">
		            <match field="data">16777236</match>
		        </input>
		        <output type="ignition.msgs.Twist" topic="/model/elgooso/cmd_vel">
		            linear: {x: 0.0}, angular: {z: -0.5}
		        </output>
		    </plugin>

		    <!--Rotating left-->
		    <plugin filename="libignition-gazebo-triggered-publisher-system.so"
		            name="ignition::gazebo::systems::TriggeredPublisher">
		        <input type="ignition.msgs.Int32" topic="/keyboard/keypress">
		            <match field="data">16777234</match>
		        </input>
		        <output type="ignition.msgs.Twist" topic="/model/elgooso/cmd_vel">
		            linear: {x: 0.0}, angular: {z: 0.5}
		        </output>
		    </plugin>
			
		</model>
    </world>
</sdf>
